Workbook

Sheet 20221207
A1: (estimate) | B1: 2308 | C1: 2330 | D1: 2357 | E1: 2897 | G1: price | H1: 2308 | I1: 2330 | J1: 2357 | K1: 2897
A2: weight | B2: 0.24465535 | C2: 1.0511294e-07 | D2: 0.38983068 | E2: 0.36551387 | G2: 44895 | H2: 305 | I2: 492.5 | J2: 277 | K2: 8.58 | L2: (reference price)
A3: value | B3: 7528 | C3: 0 | D3: 11994 | E3: 11246 | G3: 44902 | H3: 296 | I3: 478 | J3: 273.5 | K3: 8.525483 | L3: (done price)
A4: total amount | B4: 24.681967 | C4: 0 | D4: 43.299639 | E4: 1310.7226 | G4: 44925 | H4: 286.5 | I4: 448.5 | J4: 268.5 | K4: 8.39 | L4: (observation price)
A5: last amount | B5: 20 | C5: 0 | D5: 30 | E5: 741
A6: change | B6: 4.6819672 | C6: 0 | D6: 13.299639 | E6: 569.72261 | G6: value | H6: 2308 | I6: 2330 | J6: 2357 | K6: 2897 | L6: Total | M6: Original Invest | N6: Return (%)
G7: 44895 | H7: =B5*H2 -> 6100 | I7: =C5*I2 -> 0 | J7: =D5*J2 -> 8310 | K7: =E5*K2 -> 6357.78 | L7: =SUM(H7:K7) -> 20767.78 | M7: 20000 | N7: =(L7/M7 - 1) * 100 -> 3.8389
A8: (real) | B8: 2308 | C8: 2330 | D8: 2357 | E8: 2897 | G8: 44902 | H8: =B11*H3 -> 7104 | I8: =C11*I3 -> 0 | J8: =D11*J3 -> 11760.5 | K8: =E11*K3 -> 11168.383 | L8: =SUM(H8:K8) -> 30032.883 | M8: =ROUNDUP(20000+B13*H3+C13*I3+D13*J3+E13*K3, 0)+3 -> 29594 | N8: =(L8/M8 - 1) * 100 -> 1.4830125
A9: weight | B9: =B10/L8 -> 0.23654073 | C9: =C10/L8 -> 0 | D9: =D10/L8 -> 0.39158745 | E9: =E10/L8 -> 0.37187182 | G9: 44925 | H9: =B11*H4 -> 6876 | I9: =C11*I4 -> 0 | J9: =D11*J4 -> 11545.5 | K9: =E11*K4 -> 10990.9 | L9: =SUM(H9:K9) -> 29412.4 | M9: =M8 -> 29594 | N9: =(L9/M9 - 1) * 100 -> -0.6136379
A10: value | B10: =B11*H3 -> 7104 | C10: =C11*I3 -> 0 | D10: =D11*J3 -> 11760.5 | E10: =E11*K3 -> 11168.383
A11: total amount | B11: =B12+B13 -> 24 | C11: =C12+C13 -> 0 | D11: =D12+D13 -> 43 | E11: =E12+E13 -> 1310
A12: last amount | B12: 20 | C12: 0 | D12: 30 | E12: 741
A13: change | B13: 4 | C13: 0 | D13: 13 | E13: 569
A14: change value | B14: =ROUND(B13*H3,0) -> 1184 | C14: =ROUND(C13*I3,0) -> 0 | D14: =ROUND(D13*J3,0) -> 3556 | E14: =ROUND(E13*K3,0) -> 4851
A16: target return (monthly) (%) | B16: 1.65
A17: risk(std) | B17: 5.08

Sheet 20230109
A1: (estimate) | B1: 2308 | C1: 2330 | D1: 2357 | E1: 2897 | G1: price | H1: 2308 | I1: 2330 | J1: 2357 | K1: 2897
A2: weight | B2: 0.28491239 | C2: 8.6244379e-07 | D2: 0.40998609 | E2: 0.30510066 | G2: 44925 | H2: 286.5 | I2: 448.5 | J2: 268.5 | K2: 8.39 | L2: (reference price)
A3: value | B3: 11229 | C3: 0 | D3: 16159 | E3: 12025 | G3: 44935 | H3: 280 | I3: 481 | J3: 273.5 | K3: 8.47 | L3: (done price)
A4: total amount | B4: 39.193717 | C4: 0 | D4: 60.182495 | E4: 1433.2539 | G4: 44957 | H4: 289 | I4: 522 | J4: 272 | K4: 9.25 | L4: (observation price)
A5: last amount | B5: 24 | C5: 0 | D5: 43 | E5: 1310
A6: change | B6: 15.193717 | C6: 0 | D6: 17.182495 | E6: 123.25387 | G6: value | H6: 2308 | I6: 2330 | J6: 2357 | K6: 2897 | L6: Total | M6: Original Invest | N6: Return (%)
G7: 44925 | H7: =B5*H2 -> 6876 | I7: =C5*I2 -> 0 | J7: =D5*J2 -> 11545.5 | K7: =E5*K2 -> 10990.9 | L7: =SUM(H7:K7) -> 29412.4 | M7: ='20221207'!M8 -> 29594 | N7: =(L7/M7 - 1) * 100 -> -0.6136379
A8: (real) | B8: 2308 | C8: 2330 | D8: 2357 | E8: 2897 | G8: 44935 | H8: =B11*H3 -> 10920 | I8: =C11*I3 -> 0 | J8: =D11*J3 -> 16410 | K8: =E11*K3 -> 12137.51 | L8: =SUM(H8:K8) -> 39467.51 | M8: =ROUNDUP(M7+B13*H3+C13*I3+D13*J3+E13*K3, 0)+3 -> 39489 | N8: =(L8/M8 - 1) * 100 -> -0.054420218
A9: weight | B9: =B10/L8 -> 0.27668328 | C9: =C10/L8 -> 0 | D9: =D10/L8 -> 0.41578503 | E9: =E10/L8 -> 0.30753169 | G9: 47149 | H9: =B11*H4 -> 11271 | I9: =C11*I4 -> 0 | J9: =D11*J4 -> 16320 | K9: =E11*K4 -> 13255.25 | L9: =SUM(H9:K9) -> 40846.25 | M9: =M8 -> 39489 | N9: =(L9/M9 - 1) * 100 -> 3.4370331
A10: value | B10: =B11*H3 -> 10920 | C10: =C11*I3 -> 0 | D10: =D11*J3 -> 16410 | E10: =E11*K3 -> 12137.51
A11: total amount | B11: =B12+B13 -> 39 | C11: =C12+C13 -> 0 | D11: =D12+D13 -> 60 | E11: =E12+E13 -> 1433
A12: last amount | B12: 24 | C12: 0 | D12: 43 | E12: 1310
A13: change | B13: 15 | C13: 0 | D13: 17 | E13: 123
A14: change value | B14: =ROUND(B13*H3,0) -> 4200 | C14: =ROUND(C13*I3,0) -> 0 | D14: =ROUND(D13*J3,0) -> 4650 | E14: =ROUND(E13*K3,0) -> 1042
A16: target return (monthly) (%) | B16: 1.65
A17: risk(std) | B17: 5.23

Sheet 20230208
A1: (estimate) | B1: 2308 | C1: 2330 | D1: 2357 | E1: 2897 | G1: price | H1: 2308 | I1: 2330 | J1: 2357 | K1: 2897
A2: weight | B2: 0.2546399 | C2: 1.3462732e-07 | D2: 0.39462832 | E2: 0.35073165 | G2: 44957 | H2: 289 | I2: 522 | J2: 272 | K2: 9.25 | L2: (reference price)
A3: value | B3: 12947 | C3: 0 | D3: 20065 | E3: 17833 | G3: 44965 | H3: 296 | I3: 540 | J3: 278 | K3: 9.68 | L3: (done price)
A4: total amount | B4: 44.799308 | C4: 0 | D4: 73.768382 | E4: 1927.8919 | G4: 44981 | H4: 286.5 | I4: 511 | J4: 278 | K4: 9.71 | L4: (observation price)
A5: last amount | B5: 39 | C5: 0 | D5: 60 | E5: 1433
A6: change | B6: 5.799308 | C6: 0 | D6: 13.768382 | E6: 494.89189 | G6: value | H6: 2308 | I6: 2330 | J6: 2357 | K6: 2897 | L6: Total | M6: Original Invest | N6: Return (%)
G7: 44957 | H7: =B5*H2 -> 11271 | I7: =C5*I2 -> 0 | J7: =D5*J2 -> 16320 | K7: =E5*K2 -> 13255.25 | L7: =SUM(H7:K7) -> 40846.25 | M7: ='20230109'!M8 -> 39489 | N7: =(L7/M7 - 1) * 100 -> 3.4370331
A8: (real) | B8: 2308 | C8: 2330 | D8: 2357 | E8: 2897 | G8: 44965 | H8: =B11*H3 -> 13320 | I8: =C11*I3 -> 0 | J8: =D11*J3 -> 20572 | K8: =E11*K3 -> 18663.04 | L8: =SUM(H8:K8) -> 52555.04 | M8: =ROUNDUP(M7+B13*H3+C13*I3+D13*J3+E13*K3, 0)+3 -> 49952 | N8: =(L8/M8 - 1) * 100 -> 5.2110826
A9: weight | B9: =B10/L8 -> 0.25344858 | C9: =C10/L8 -> 0 | D9: =D10/L8 -> 0.39143724 | E9: =E10/L8 -> 0.35511418 | G9: 44981 | H9: =B11*H4 -> 12892.5 | I9: =C11*I4 -> 0 | J9: =D11*J4 -> 20572 | K9: =E11*K4 -> 18720.88 | L9: =SUM(H9:K9) -> 52185.38 | M9: =M8 -> 49952 | N9: =(L9/M9 - 1) * 100 -> 4.4710522
A10: value | B10: =B11*H3 -> 13320 | C10: =C11*I3 -> 0 | D10: =D11*J3 -> 20572 | E10: =E11*K3 -> 18663.04
A11: total amount | B11: =B12+B13 -> 45 | C11: =C12+C13 -> 0 | D11: =D12+D13 -> 74 | E11: =E12+E13 -> 1928
A12: last amount | B12: 39 | C12: 0 | D12: 60 | E12: 1433
A13: change | B13: 6 | C13: 0 | D13: 14 | E13: 495
A14: change value | B14: =ROUND(B13*H3,0) -> 1776 | C14: =ROUND(C13*I3,0) -> 0 | D14: =ROUND(D13*J3,0) -> 3892 | E14: =ROUND(E13*K3,0) -> 4792
A16: target return (monthly) (%) | B16: 1.65
A17: risk(std) | B17: 5.08

Sheet 20230306
A1: (estimate) | B1: 2308 | C1: 2330 | D1: 2357 | E1: 2897 | G1: price | H1: 2308 | I1: 2330 | J1: 2357 | K1: 2897
A2: weight | B2: 0.24224934 | C2: 1.6738268e-07 | D2: 0.39214988 | E2: 0.36560061 | G2: 44981 | H2: 286.5 | I2: 511 | J2: 278 | K2: 9.71 | L2: (reference price)
A3: value | B3: 15064 | C3: 0 | D3: 24386 | E3: 22735 | G3: 44993 | H3: 298.5 | I3: 521 | J3: 287 | K3: 9.76 | L3: (done price)
A4: total amount | B4: 52.579407 | C4: 0 | D4: 87.719424 | E4: 2341.4006 | G4: 45016 | H4: 301 | I4: 533 | J4: 272.5 | K4: 9.68 | L4: (observation price)
A5: last amount | B5: 45 | C5: 0 | D5: 74 | E5: 1928
A6: change | B6: 7.5794066 | C6: 0 | D6: 13.719424 | E6: 413.40062 | G6: value | H6: 2308 | I6: 2330 | J6: 2357 | K6: 2897 | L6: Total | M6: Original Invest | N6: Return (%)
G7: 44981 | H7: =B5*H2 -> 12892.5 | I7: =C5*I2 -> 0 | J7: =D5*J2 -> 20572 | K7: =E5*K2 -> 18720.88 | L7: =SUM(H7:K7) -> 52185.38 | M7: ='20230208'!M8 -> 49952 | N7: =(L7/M7 - 1) * 100 -> 4.4710522
A8: (real) | B8: 2308 | C8: 2330 | D8: 2357 | E8: 2897 | G8: 44993 | H8: =B11*H3 -> 15522 | I8: =C11*I3 -> 0 | J8: =D11*J3 -> 25256 | K8: =E11*K3 -> 22848.16 | L8: =SUM(H8:K8) -> 63626.16 | M8: =ROUNDUP(M7+B13*H3+C13*I3+D13*J3+E13*K3, 0)+4 -> 60095 | N8: =(L8/M8 - 1) * 100 -> 5.8759631
A9: weight | B9: =B10/L8 -> 0.24395626 | C9: =C10/L8 -> 0 | D9: =D10/L8 -> 0.39694365 | E9: =E10/L8 -> 0.35910009 | G9: 45016 | H9: =B11*H4 -> 15652 | I9: =C11*I4 -> 0 | J9: =D11*J4 -> 23980 | K9: =E11*K4 -> 22660.88 | L9: =SUM(H9:K9) -> 62292.88 | M9: =M8 -> 60095 | N9: =(L9/M9 - 1) * 100 -> 3.6573425
A10: value | B10: =B11*H3 -> 15522 | C10: =C11*I3 -> 0 | D10: =D11*J3 -> 25256 | E10: =E11*K3 -> 22848.16
A11: total amount | B11: =B12+B13 -> 52 | C11: =C12+C13 -> 0 | D11: =D12+D13 -> 88 | E11: =E12+E13 -> 2341
A12: last amount | B12: 45 | C12: 0 | D12: 74 | E12: 1928
A13: change | B13: 7 | C13: 0 | D13: 14 | E13: 413
A14: change value | B14: =ROUND(B13*H3,0) -> 2090 | C14: =ROUND(C13*I3,0) -> 0 | D14: =ROUND(D13*J3,0) -> 4018 | E14: =ROUND(E13*K3,0) -> 4031
A16: target return (monthly) (%) | B16: 1.65
A17: risk(std) | B17: 4.99

Sheet 20230407
A1: (estimate) | B1: 2308 | C1: 2330 | D1: 2357 | E1: 2897 | G1: price | H1: 2308 | I1: 2330 | J1: 2357 | K1: 2897
A2: weight | B2: 0.26726072 | C2: 1.464884e-07 | D2: 0.38295437 | E2: 0.34978477 | G2: 45016 | H2: 301 | I2: 533 | J2: 272.5 | K2: 9.68 | L2: (reference price)
A3: value | B3: 19321 | C3: 0 | D3: 27685 | E3: 25287 | G3: 45023 | H3: 294 | I3: 531 | J3: 272 | K3: 9.84 | L3: (done price)
A4: total amount | B4: 64.189369 | C4: 0 | D4: 101.59633 | E4: 2612.2934 | G4: 45044 | H4: 300 | I4: 502 | J4: 282.5 | K4: 10.25 | L4: (observation price)
A5: last amount | B5: 52 | C5: 0 | D5: 88 | E5: 2341
A6: change | B6: 12.189369 | C6: 0 | D6: 13.59633 | E6: 271.29339 | G6: value | H6: 2308 | I6: 2330 | J6: 2357 | K6: 2897 | L6: Total | M6: Original Invest | N6: Return (%)
G7: 45016 | H7: =B5*H2 -> 15652 | I7: =C5*I2 -> 0 | J7: =D5*J2 -> 23980 | K7: =E5*K2 -> 22660.88 | L7: =SUM(H7:K7) -> 62292.88 | M7: ='20230306'!M8 -> 60095 | N7: =(L7/M7 - 1) * 100 -> 3.6573425
A8: (real) | B8: 2308 | C8: 2330 | D8: 2357 | E8: 2897 | G8: 45023 | H8: =B11*H3 -> 18816 | I8: =C11*I3 -> 0 | J8: =D11*J3 -> 27744 | K8: =E11*K3 -> 25702.08 | L8: =SUM(H8:K8) -> 72262.08 | M8: =ROUNDUP(M7+B13*H3+C13*I3+D13*J3+E13*K3, 0)+3 -> 70101 | N8: =(L8/M8 - 1) * 100 -> 3.0828091
A9: weight | B9: =B10/L8 -> 0.26038553 | C9: =C10/L8 -> 0 | D9: =D10/L8 -> 0.38393581 | E9: =E10/L8 -> 0.35567866 | G9: 45044 | H9: =B11*H4 -> 19200 | I9: =C11*I4 -> 0 | J9: =D11*J4 -> 28815 | K9: =E11*K4 -> 26773 | L9: =SUM(H9:K9) -> 74788 | M9: =M8 -> 70101 | N9: =(L9/M9 - 1) * 100 -> 6.6860672
A10: value | B10: =B11*H3 -> 18816 | C10: =C11*I3 -> 0 | D10: =D11*J3 -> 27744 | E10: =E11*K3 -> 25702.08
A11: total amount | B11: =B12+B13 -> 64 | C11: =C12+C13 -> 0 | D11: =D12+D13 -> 102 | E11: =E12+E13 -> 2612
A12: last amount | B12: 52 | C12: 0 | D12: 88 | E12: 2341
A13: change | B13: 12 | C13: 0 | D13: 14 | E13: 271
A14: change value | B14: =ROUND(B13*H3,0) -> 3528 | C14: =ROUND(C13*I3,0) -> 0 | D14: =ROUND(D13*J3,0) -> 3808 | E14: =ROUND(E13*K3,0) -> 2667
A16: target return (monthly) (%) | B16: 1.65
A17: risk(std) | B17: 4.98

Sheet 20230508
A1: (estimate) | B1: 2308 | C1: 2330 | D1: 2357 | E1: 2897 | G1: price | H1: 2308 | I1: 2330 | J1: 2357 | K1: 2897
A2: weight | B2: 0.23633078 | C2: 1.6089926e-07 | D2: 0.38084321 | E2: 0.38282585 | G2: 45044 | H2: 300 | I2: 502 | J2: 282.5 | K2: 10.25 | L2: (reference price)
A3: value | B3: 20038 | C3: 0 | D3: 32291 | E3: 32459 | G3: 45054 | H3: 303 | I3: 504 | J3: 288.5 | K3: 9.98 | L3: (done price)
A4: total amount | B4: 66.793333 | C4: 0 | D4: 114.30442 | E4: 3166.7317 | G4: 45077 | H4: 316.5 | I4: 558 | J4: 305 | K4: 10.3 | L4: (observation price)
A5: last amount | B5: 64 | C5: 0 | D5: 102 | E5: 2612
A6: change | B6: 2.7933333 | C6: 0 | D6: 12.304425 | E6: 554.73171 | G6: value | H6: 2308 | I6: 2330 | J6: 2357 | K6: 2897 | L6: Total | M6: Original Invest | N6: Return (%)
G7: 45044 | H7: =B5*H2 -> 19200 | I7: =C5*I2 -> 0 | J7: =D5*J2 -> 28815 | K7: =E5*K2 -> 26773 | L7: =SUM(H7:K7) -> 74788 | M7: ='20230407'!M8 -> 70101 | N7: =(L7/M7 - 1) * 100 -> 6.6860672
A8: (real) | B8: 2308 | C8: 2330 | D8: 2357 | E8: 2897 | G8: 45054 | H8: =B11*H3 -> 20301 | I8: =C11*I3 -> 0 | J8: =D11*J3 -> 32889 | K8: =E11*K3 -> 31606.66 | L8: =SUM(H8:K8) -> 84796.66 | M8: =ROUNDUP(M7+B13*H3+C13*I3+D13*J3+E13*K3, 0)+3 -> 80014 | N8: =(L8/M8 - 1) * 100 -> 5.977279
A9: weight | B9: =B10/L8 -> 0.23940801 | C9: =C10/L8 -> 0 | D9: =D10/L8 -> 0.38785726 | E9: =E10/L8 -> 0.37273473 | G9: 45077 | H9: =B11*H4 -> 21205.5 | I9: =C11*I4 -> 0 | J9: =D11*J4 -> 34770 | K9: =E11*K4 -> 32620.1 | L9: =SUM(H9:K9) -> 88595.6 | M9: =M8 -> 80014 | N9: =(L9/M9 - 1) * 100 -> 10.725123
A10: value | B10: =B11*H3 -> 20301 | C10: =C11*I3 -> 0 | D10: =D11*J3 -> 32889 | E10: =E11*K3 -> 31606.66
A11: total amount | B11: =B12+B13 -> 67 | C11: =C12+C13 -> 0 | D11: =D12+D13 -> 114 | E11: =E12+E13 -> 3167
A12: last amount | B12: 64 | C12: 0 | D12: 102 | E12: 2612
A13: change | B13: 3 | C13: 0 | D13: 12 | E13: 555
A14: change value | B14: =ROUND(B13*H3,0) -> 909 | C14: =ROUND(C13*I3,0) -> 0 | D14: =ROUND(D13*J3,0) -> 3462 | E14: =ROUND(E13*K3,0) -> 5539
A16: target return (monthly) (%) | B16: 1.65
A17: risk(std) | B17: 4.87

Sheet 20230608
A1: (estimate) | B1: 2308 | C1: 2330 | D1: 2357 | E1: 2897 | G1: price | H1: 2308 | I1: 2330 | J1: 2357 | K1: 2897
A2: weight | B2: 0.18973805 | C2: 2.3198898e-06 | D2: 0.37721829 | E2: 0.43304134 | G2: 45077 | H2: 316.5 | I2: 558 | J2: 305 | K2: 10.3 | L2: (reference price)
A3: value | B3: 18707 | C3: 0 | D3: 37192 | E3: 42696 | G3: 45085 | H3: 329 | I3: 559 | J3: 312.5 | K3: 10.3 | L3: (done price)
A4: total amount | B4: 59.105845 | C4: 0 | D4: 121.94098 | E4: 4145.2427 | G4: 45107 | H4: 339.66 | I4: 570.33 | J4: 314 | K4: 10.05 | L4: (observation price)
A5: last amount | B5: 67 | C5: 0 | D5: 114 | E5: 3167
A6: change | B6: -7.8941548 | C6: 0 | D6: 7.9409836 | E6: 978.24272 | G6: value | H6: 2308 | I6: 2330 | J6: 2357 | K6: 2897 | L6: Total | M6: Original Invest | N6: Return (%)
G7: 45077 | H7: =B5*H2 -> 21205.5 | I7: =C5*I2 -> 0 | J7: =D5*J2 -> 34770 | K7: =E5*K2 -> 32620.1 | L7: =SUM(H7:K7) -> 88595.6 | M7: ='20230508'!M8 -> 80014 | N7: =(L7/M7 - 1) * 100 -> 10.725123
A8: (real) | B8: 2308 | C8: 2330 | D8: 2357 | E8: 2897 | G8: 45085 | H8: =B11*H3 -> 19411 | I8: =C11*I3 -> 0 | J8: =D11*J3 -> 38125 | K8: =E11*K3 -> 42693.5 | L8: =SUM(H8:K8) -> 100229.5 | M8: =ROUNDUP(M7+B13*H3+C13*I3+D13*J3+E13*K3, 0)+13 -> 89969 | N8: =(L8/M8 - 1) * 100 -> 11.404484
A9: weight | B9: =B10/$L$8 -> 0.19366554 | C9: =C10/$L$8 -> 0 | D9: =D10/$L$8 -> 0.38037703 | E9: =E10/$L$8 -> 0.42595743 | G9: 45107 | H9: =B11*H4 -> 20039.94 | I9: =C11*I4 -> 0 | J9: =D11*J4 -> 38308 | K9: =E11*K4 -> 41657.25 | L9: =SUM(H9:K9)+H13 -> 100575.19 | M9: =M8 -> 89969 | N9: =(L9/M9 - 1) * 100 -> 11.788716
A10: value | B10: =B11*H3 -> 19411 | C10: =C11*I3 -> 0 | D10: =D11*J3 -> 38125 | E10: =E11*K3 -> 42693.5
A11: total amount | B11: =B12+B13 -> 59 | C11: =C12+C13 -> 0 | D11: =D12+D13 -> 122 | E11: =E12+E13 -> 4145
A12: last amount | B12: 67 | C12: 0 | D12: 114 | E12: 3167 | G12: Note: 6/30 2308 dividend $9.84
A13: change | B13: -8 | C13: 0 | D13: 8 | E13: 978 | G13: dividend = | H13: 570
A14: change value | B14: =ROUND(B13*H3,0) -> -2632 | C14: =ROUND(C13*I3,0) -> 0 | D14: =ROUND(D13*J3,0) -> 2500 | E14: =ROUND(E13*K3,0) -> 10073 | G14: total div = | H14: 570
A16: target return (monthly) (%) | B16: 1.65
A17: risk(std) | B17: 4.77

Sheet 20230707
A1: (estimate) | B1: 2308 | C1: 2330 | D1: 2357 | E1: 2897 | G1: price | H1: 2308 | I1: 2330 | J1: 2357 | K1: 2897
A2: weight | B2: 0.212989 | C2: 6.6847021e-08 | D2: 0.38112584 | E2: 0.4058851 | G2: 45107 | H2: 339.66 | I2: 570.33 | J2: 314 | K2: 10.05 | L2: (reference price)
A3: value | B3: 23430 | C3: 0 | D3: 41926 | E3: 44649 | G3: 45114 | H3: 353 | I3: 565 | J3: 298 | K3: 10 | L3: (done price)
A4: total amount | B4: 68.980745 | C4: 0 | D4: 133.52229 | E4: 4442.6866 | G4: 45138 | H4: 365.5 | I4: 565 | J4: 364 | K4: 9.98 | L4: (observation price)
A5: last amount | B5: 59 | C5: 0 | D5: 122 | E5: 4145
A6: change | B6: 9.9807446 | C6: 0 | D6: 11.522293 | E6: 297.68657 | G6: value | H6: 2308 | I6: 2330 | J6: 2357 | K6: 2897 | L6: Total | M6: Original Invest | N6: Return (%)
G7: 45107 | H7: =B5*H2 -> 20039.94 | I7: =C5*I2 -> 0 | J7: =D5*J2 -> 38308 | K7: =E5*K2 -> 41657.25 | L7: ='20230608'!L9 -> 100575.19 | M7: ='20230608'!M8 -> 89969 | N7: =(L7/M7 - 1) * 100 -> 11.788716
A8: (real) | B8: 2308 | C8: 2330 | D8: 2357 | E8: 2897 | G8: 45114 | H8: =B11*H3 -> 24357 | I8: =C11*I3 -> 0 | J8: =D11*J3 -> 39634 | K8: =E11*K3 -> 44430 | L8: =SUM(H8:K8)+H14 -> 112499.34 | M8: =ROUNDUP(M7+B13*H3+C13*I3+D13*J3+E13*K3, 0)+3 -> 99760 | N8: =(L8/M8 - 1) * 100 -> 12.769988
A9: weight | B9: =B10/$L$8 -> 0.21650794 | C9: =C10/$L$8 -> 0 | D9: =D10/$L$8 -> 0.35230429 | E9: =E10/$L$8 -> 0.39493565 | G9: 45138 | H9: =B11*H4 -> 25219.5 | I9: =C11*I4 -> 0 | J9: =D11*J4 -> 48412 | K9: =E11*K4 -> 44341.14 | L9: =SUM(H9:K9)+H14 -> 122050.98 | M9: =M8 -> 99760 | N9: =(L9/M9 - 1) * 100 -> 22.344607
A10: value | B10: =B11*H3 -> 24357 | C10: =C11*I3 -> 0 | D10: =D11*J3 -> 39634 | E10: =E11*K3 -> 44430
A11: total amount | B11: =B12+B13 -> 69 | C11: =C12+C13 -> 0 | D11: =D12+D13 -> 133 | E11: =E12+E13 -> 4443
A12: last amount | B12: 59 | C12: 0 | D12: 122 | E12: 4145 | G12: Note: 7/4 2357 dividend $15, 7/27 2897 dividend $0.38
A13: change | B13: 10 | C13: 0 | D13: 11 | E13: 298 | G13: dividend = | H13: =1820+E11*0.38 -> 3508.34
A14: change value | B14: =ROUND(B13*H3,0) -> 3530 | C14: =ROUND(C13*I3,0) -> 0 | D14: =ROUND(D13*J3,0) -> 3278 | E14: =ROUND(E13*K3,0) -> 2980 | G14: total div = | H14: =H13+'20230608'!H14 -> 4078.34
A16: target return (monthly) (%) | B16: 1.7
A17: risk(std) | B17: 4.74

Sheet 20230808
A1: (estimate) | B1: 2308 | C1: 2330 | D1: 2357 | E1: 2897 | G1: price | H1: 2308 | I1: 2330 | J1: 2357 | K1: 2897
A2: weight | B2: 0.18217442 | C2: 8.0169581e-08 | D2: 0.36173345 | E2: 0.45609204 | G2: 45138 | H2: 365.5 | I2: 565 | J2: 364 | K2: 9.98 | L2: (reference price)
A3: value | B3: 22591 | C3: 0 | D3: 44857 | E3: 56558 | G3: 45146 | H3: 364 | I3: 552 | J3: 370.5 | K3: 9.91 | L3: (done price)
A4: total amount | B4: 61.808482 | C4: 0 | D4: 129.44697 | E4: 5885.3223 | G4: 45169 | H4: 346 | I4: 549 | J4: 402.5 | K4: 9.5 | L4: (observation price)
A5: last amount | B5: 69 | C5: 0 | D5: 133 | E5: 4443
A6: change | B6: -7.1915185 | C6: 0 | D6: -3.5530345 | E6: 1442.3223 | G6: value | H6: 2308 | I6: 2330 | J6: 2357 | K6: 2897 | L6: Total Value | M6: Total Return | N6: Original Invest | O6: Return (%)
G7: 45138 | H7: =B5*H2 -> 25219.5 | I7: =C5*I2 -> 0 | J7: =D5*J2 -> 48412 | K7: =E5*K2 -> 44341.14 | L7: =SUM(H7:K7) -> 117972.64 | M7: ='20230707'!L9 -> 122050.98 | N7: ='20230707'!M8 -> 99760 | O7: =(M7/N7 - 1) * 100 -> 22.344607
A8: (real) | B8: 2308 | C8: 2330 | D8: 2357 | E8: 2897 | G8: 45146 | H8: =B11*H3 -> 22568 | I8: =C11*I3 -> 0 | J8: =D11*J3 -> 47794.5 | K8: =E11*K3 -> 58320.35 | L8: =SUM(H8:K8) -> 128682.85 | M8: =L8+H14-H15 -> 132727.19 | N8: =ROUNDUP(N7+B13*H3+C13*I3+D13*J3+E13*K3, 0) -> 110021 | O8: =(M8/N8 - 1) * 100 -> 20.638051
A9: weight | B9: =B10/$L$8 -> 0.17537691 | C9: =C10/$L$8 -> 0 | D9: =D10/$L$8 -> 0.37141313 | E9: =E10/$L$8 -> 0.45320997 | G9: 45169 | H9: =B11*H4 -> 21452 | I9: =C11*I4 -> 0 | J9: =D11*J4 -> 51922.5 | K9: =E11*K4 -> 55907.5 | L9: =SUM(H9:K9) -> 129282 | M9: =L9+H14-H15 -> 133326.34 | N9: =N8 -> 110021 | O9: =(M9/N9 - 1) * 100 -> 21.182629
A10: value | B10: =B11*H3 -> 22568 | C10: =C11*I3 -> 0 | D10: =D11*J3 -> 47794.5 | E10: =E11*K3 -> 58320.35
A11: total amount | B11: =B12+B13 -> 62 | C11: =C12+C13 -> 0 | D11: =D12+D13 -> 129 | E11: =E12+E13 -> 5885
A12: last amount | B12: 69 | C12: 0 | D12: 133 | E12: 4443 | G12: Note:
A13: change | B13: -7 | C13: 0 | D13: -4 | E13: 1442 | G13: dividend = | H13: 0
A14: change value | B14: =ROUND(B13*H3,0) -> -2548 | C14: =ROUND(C13*I3,0) -> 0 | D14: =ROUND(D13*J3,0) -> -1482 | E14: =ROUND(E13*K3,0) -> 14290 | G14: total div = | H14: ='20230707'!H14+H13 -> 4078.34
G15: charge&tax | H15: 34
A16: target return (monthly) (%) | B16: 1.75
A17: risk(std) | B17: 4.71
A18: VaR(95%) | B18: -9280

Sheet 20230907
A1: (estimate) | B1: 2308 | C1: 2330 | D1: 2357 | E1: 2897 | G1: price | H1: 2308 | I1: 2330 | J1: 2357 | K1: 2897
A2: weight | B2: 0.18263334 | C2: 5.4307231e-08 | D2: 0.35673463 | E2: 0.46063198 | G2: 45169 | H2: 346 | I2: 549 | J2: 402.5 | K2: 9.5 | L2: (reference price)
A3: value | B3: 25438 | C3: 0 | D3: 49687 | E3: 64158 | G3: 45176 | H3: 345 | I3: 542 | J3: 400 | K3: 9.93 | L3: (done price)
A4: total amount | B4: 73.520231 | C4: 0 | D4: 123.44596 | E4: 6753.4737 | G4: 45197 | H4: 324.5 | I4: 523 | J4: 367 | K4: 9.51 | L4: (observation price)
A5: last amount | B5: 62 | C5: 0 | D5: 129 | E5: 5885
A6: change | B6: 11.520231 | C6: 0 | D6: -5.5540373 | E6: 868.47368 | G6: value | H6: 2308 | I6: 2330 | J6: 2357 | K6: 2897 | L6: Total Value | M6: Total Return | N6: Original Invest | O6: Return (%)
G7: 45169 | H7: =B5*H2 -> 21452 | I7: =C5*I2 -> 0 | J7: =D5*J2 -> 51922.5 | K7: =E5*K2 -> 55907.5 | L7: =SUM(H7:K7) -> 129282 | M7: ='20230808'!M9 -> 133326.34 | N7: ='20230808'!N8 -> 110021 | O7: =(M7/N7 - 1) * 100 -> 21.182629
A8: (real) | B8: 2308 | C8: 2330 | D8: 2357 | E8: 2897 | G8: 45176 | H8: =B11*H3 -> 25530 | I8: =C11*I3 -> 0 | J8: =D11*J3 -> 49200 | K8: =E11*K3 -> 67057.29 | L8: =SUM(H8:K8) -> 141787.29 | M8: =L8+H14-H15 -> 145819.63 | N8: =ROUNDUP(N7+B13*H3+C13*I3+D13*J3+E13*K3, 0) -> 120381 | O8: =(M8/N8 - 1) * 100 -> 21.131765
A9: weight | B9: =B10/$L$8 -> 0.18005845 | C9: =C10/$L$8 -> 0 | D9: =D10/$L$8 -> 0.34699866 | E9: =E10/$L$8 -> 0.47294289 | G9: 45199 | H9: =B11*H4 -> 24013 | I9: =C11*I4 -> 0 | J9: =D11*J4 -> 45141 | K9: =E11*K4 -> 64221.03 | L9: =SUM(H9:K9) -> 133375.03 | M9: =L9+H14-H15 -> 137407.37 | N9: =N8 -> 120381 | O9: =(M9/N9 - 1) * 100 -> 14.143735
A10: value | B10: =B11*H3 -> 25530 | C10: =C11*I3 -> 0 | D10: =D11*J3 -> 49200 | E10: =E11*K3 -> 67057.29
A11: total amount | B11: =B12+B13 -> 74 | C11: =C12+C13 -> 0 | D11: =D12+D13 -> 123 | E11: =E12+E13 -> 6753
A12: last amount | B12: 62 | C12: 0 | D12: 129 | E12: 5885 | G12: Note:
A13: change | B13: 12 | C13: 0 | D13: -6 | E13: 868 | G13: dividend = | H13: 0
A14: change value | B14: =ROUND(B13*H3,0) -> 4140 | C14: =ROUND(C13*I3,0) -> 0 | D14: =ROUND(D13*J3,0) -> -2400 | E14: =ROUND(E13*K3,0) -> 8619 | G14: total div = | H14: ='20230808'!H14+H13 -> 4078.34
G15: charge&tax | H15: ='20230808'!H15+12 -> 46
A16: target return (monthly) (%) | B16: 1.8
A17: risk(std) | B17: 4.67
A18: VaR(95%) | B18: -10245

Sheet 20231006
A1: (estimate) | B1: 2308 | C1: 2330 | D1: 2357 | E1: 2897 | G1: price | H1: 2308 | I1: 2330 | J1: 2357 | K1: 2897
A2: weight | B2: 0.24426074 | C2: 1.3179332e-07 | D2: 0.38634625 | E2: 0.36939288 | G2: 45197 | H2: 324.5 | I2: 523 | J2: 367 | K2: 9.51 | L2: (reference price)
A3: value | B3: 35021 | C3: 0 | D3: 55392 | E3: 52962 | G3: 45205 | H3: 338 | I3: 532 | J3: 380 | K3: 9.41 | L3: (done price)
A4: total amount | B4: 107.92296 | C4: 0 | D4: 150.93188 | E4: 5569.0852 | G4: 45230 | H4: 290.5 | I4: 529 | J4: 338 | K4: 9.32 | L4: (observation price)
A5: last amount | B5: 74 | C5: 0 | D5: 123 | E5: 6753
A6: change | B6: 33.922958 | C6: 0 | D6: 27.93188 | E6: -1183.9148 | G6: value | H6: 2308 | I6: 2330 | J6: 2357 | K6: 2897 | L6: Total Value | M6: Total Return | N6: Original Invest | O6: Return (%)
G7: 45197 | H7: =B5*H2 -> 24013 | I7: =C5*I2 -> 0 | J7: =D5*J2 -> 45141 | K7: =E5*K2 -> 64221.03 | L7: =SUM(H7:K7) -> 133375.03 | M7: ='20230907'!M9 -> 137407.37 | N7: ='20230907'!N8 -> 120381 | O7: =(M7/N7 - 1) * 100 -> 14.143735
A8: (real) | B8: 2308 | C8: 2330 | D8: 2357 | E8: 2897 | G8: 45205 | H8: =B11*H3 -> 36504 | I8: =C11*I3 -> 0 | J8: =D11*J3 -> 57380 | K8: =E11*K3 -> 52404.29 | L8: =SUM(H8:K8) -> 146288.29 | M8: =L8+H14-H15 -> 150274.63 | N8: =ROUNDUP(N7+B13*H3+C13*I3+D13*J3+E13*K3, 0) -> 131372 | O8: =(M8/N8 - 1) * 100 -> 14.388629
A9: weight | B9: =B10/$L$8 -> 0.24953467 | C9: =C10/$L$8 -> 0 | D9: =D10/$L$8 -> 0.39223919 | E9: =E10/$L$8 -> 0.35822614 | G9: 45230 | H9: =B11*H4 -> 31374 | I9: =C11*I4 -> 0 | J9: =D11*J4 -> 51038 | K9: =E11*K4 -> 51903.08 | L9: =SUM(H9:K9) -> 134315.08 | M9: =L9+H14-H15 -> 138301.42 | N9: =N8 -> 131372 | O9: =(M9/N9 - 1) * 100 -> 5.2746552
A10: value | B10: =B11*H3 -> 36504 | C10: =C11*I3 -> 0 | D10: =D11*J3 -> 57380 | E10: =E11*K3 -> 52404.29
A11: total amount | B11: =B12+B13 -> 108 | C11: =C12+C13 -> 0 | D11: =D12+D13 -> 151 | E11: =E12+E13 -> 5569
A12: last amount | B12: 74 | C12: 0 | D12: 123 | E12: 6753 | G12: Note:
A13: change | B13: 34 | C13: 0 | D13: 28 | E13: -1184 | G13: dividend = | H13: 0
A14: change value | B14: =ROUND(B13*H3,0) -> 11492 | C14: =ROUND(C13*I3,0) -> 0 | D14: =ROUND(D13*J3,0) -> 10640 | E14: =ROUND(E13*K3,0) -> -11141 | G14: total div = | H14: ='20230907'!H14+H13 -> 4078.34
G15: charge&tax | H15: ='20230907'!H15+46 -> 92
A16: target return (monthly) (%) | B16: 1.8
A17: risk(std) | B17: 4.83
A18: VaR(95%) | B18: -10989

Sheet 20231107
A1: (estimate) | B1: 2308 | C1: 2330 | D1: 2357 | E1: 2897 | G1: price | H1: 2308 | I1: 2330 | J1: 2357 | K1: 2897
A2: weight | B2: 0.2991826 | C2: 6.7151165e-08 | D2: 0.43189503 | E2: 0.2689223 | G2: 45230 | H2: 290.5 | I2: 529 | J2: 338 | K2: 9.32 | L2: (reference price)
A3: value | B3: 43177 | C3: 0 | D3: 62329 | E3: 38810 | G3: 45237 | H3: 306.5 | I3: 552 | J3: 357 | K3: 9.542285 | L3: (done price)
A4: total amount | B4: 148.62995 | C4: 0 | D4: 184.40533 | E4: 4164.1631 | G4: 45260 | H4: 316.5 | I4: 577 | J4: 393.5 | K4: 9.72 | L4: (observation price)
A5: last amount | B5: 108 | C5: 0 | D5: 151 | E5: 5569
A6: change | B6: 40.629948 | C6: 0 | D6: 33.405325 | E6: -1404.8369 | G6: value | H6: 2308 | I6: 2330 | J6: 2357 | K6: 2897 | L6: Total Value | M6: Total Return | N6: Original Invest | O6: Return (%)
G7: 45230 | H7: =B5*H2 -> 31374 | I7: =C5*I2 -> 0 | J7: =D5*J2 -> 51038 | K7: =E5*K2 -> 51903.08 | L7: =SUM(H7:K7) -> 134315.08 | M7: ='20231006'!M9 -> 138301.42 | N7: ='20231006'!N8 -> 131372 | O7: =(M7/N7 - 1) * 100 -> 5.2746552
A8: (real) | B8: 2308 | C8: 2330 | D8: 2357 | E8: 2897 | G8: 45237 | H8: =B11*H3 -> 45668.5 | I8: =C11*I3 -> 0 | J8: =D11*J3 -> 65688 | K8: =E11*K3 -> 39734.075 | L8: =SUM(H8:K8) -> 151090.57 | M8: =L8+H14-H15 -> 155023.91 | N8: =ROUNDUP(N7+B13*H3+C13*I3+D13*J3+E13*K3, 0) -> 142313 | O8: =(M8/N8 - 1) * 100 -> 8.931661
A9: weight | B9: =B10/$L$8 -> 0.30225909 | C9: =C10/$L$8 -> 0 | D9: =D10/$L$8 -> 0.43475908 | E9: =E10/$L$8 -> 0.26298182 | G9: 45260 | H9: =B11*H4 -> 47158.5 | I9: =C11*I4 -> 0 | J9: =D11*J4 -> 72404 | K9: =E11*K4 -> 40474.08 | L9: =SUM(H9:K9) -> 160036.58 | M9: =L9+H14-H15 -> 163969.92 | N9: =N8 -> 142313 | O9: =(M9/N9 - 1) * 100 -> 15.217809
A10: value | B10: =B11*H3 -> 45668.5 | C10: =C11*I3 -> 0 | D10: =D11*J3 -> 65688 | E10: =E11*K3 -> 39734.075
A11: total amount | B11: =B12+B13 -> 149 | C11: =C12+C13 -> 0 | D11: =D12+D13 -> 184 | E11: =E12+E13 -> 4164
A12: last amount | B12: 108 | C12: 0 | D12: 151 | E12: 5569 | G12: Note:
A13: change | B13: 41 | C13: 0 | D13: 33 | E13: -1405 | G13: dividend = | H13: 0
A14: change value | B14: =ROUND(B13*H3,0) -> 12567 | C14: =ROUND(C13*I3,0) -> 0 | D14: =ROUND(D13*J3,0) -> 11781 | E14: =ROUND(E13*K3,0) -> -13407 | G14: total div = | H14: ='20231006'!H14+H13 -> 4078.34
G15: charge&tax | H15: ='20231006'!H15+53 -> 145
A16: target return (monthly) (%) | B16: 1.75
A17: risk(std) | B17: 5.17
A18: VaR(95%) | B18: -12112

Sheet 20231207
A1: (estimate) | B1: 2308 | C1: 2330 | D1: 2357 | E1: 2897 | G1: price | H1: 2308 | I1: 2330 | J1: 2357 | K1: 2897
A2: weight | B2: 0.21935423 | C2: 4.4821678e-08 | D2: 0.37129203 | E2: 0.4093537 | G2: 45260 | H2: 316.5 | I2: 577 | J2: 393.5 | K2: 9.72 | L2: (reference price)
A3: value | B3: 37298 | C3: 0 | D3: 63133 | E3: 69605 | G3: 45267 | H3: 311 | I3: 566 | J3: 394 | K3: 9.734364 | L3: (done price)
A4: total amount | B4: 117.84518 | C4: 0 | D4: 160.43964 | E4: 7161.0082 | G4: 45289 | H4: 313.5 | I4: 589.92 | J4: 489.5 | K4: 9.98 | L4: (observation price)
A5: last amount | B5: 149 | C5: 0 | D5: 184 | E5: 4164
A6: change | B6: -31.154818 | C6: 0 | D6: -23.560356 | E6: 2997.0082 | G6: value | H6: 2308 | I6: 2330 | J6: 2357 | K6: 2897 | L6: Total Value | M6: Total Return | N6: Original Invest | O6: Return (%)
G7: 45260 | H7: =B5*H2 -> 47158.5 | I7: =C5*I2 -> 0 | J7: =D5*J2 -> 72404 | K7: =E5*K2 -> 40474.08 | L7: =SUM(H7:K7) -> 160036.58 | M7: ='20231107'!M9 -> 163969.92 | N7: ='20231107'!N8 -> 142313 | O7: =(M7/N7 - 1) * 100 -> 15.217809
A8: (real) | B8: 2308 | C8: 2330 | D8: 2357 | E8: 2897 | G8: 45267 | H8: =B11*H3 -> 36698 | I8: =C11*I3 -> 0 | J8: =D11*J3 -> 63040 | K8: =E11*K3 -> 69707.781 | L8: =SUM(H8:K8) -> 169445.78 | M8: =L8+H14-H16 -> 173315.12 | N8: =ROUNDUP(N7+B13*H3+C13*I3+D13*J3+E13*K3, 0)+H15 -> 152401 | O8: =(M8/N8 - 1) * 100 -> 13.723086
A9: weight | B9: =B10/$L$8 -> 0.21657665 | C9: =C10/$L$8 -> 0 | D9: =D10/$L$8 -> 0.37203641 | E9: =E10/$L$8 -> 0.41138694 | G9: 45289 | H9: =B11*H4 -> 36993 | I9: =C11*I4 -> 0 | J9: =D11*J4 -> 78320 | K9: =E11*K4 -> 71466.78 | L9: =SUM(H9:K9) -> 186779.78 | M9: =L9+H14-H16 -> 190649.12 | N9: =N8 -> 152401 | O9: =(M9/N9 - 1) * 100 -> 25.097027
A10: value | B10: =B11*H3 -> 36698 | C10: =C11*I3 -> 0 | D10: =D11*J3 -> 63040 | E10: =E11*K3 -> 69707.781
A11: total amount | B11: =B12+B13 -> 118 | C11: =C12+C13 -> 0 | D11: =D12+D13 -> 160 | E11: =E12+E13 -> 7161
A12: last amount | B12: 149 | C12: 0 | D12: 184 | E12: 4164 | G12: Note:
A13: change | B13: -31 | C13: 0 | D13: -24 | E13: 2997 | G13: dividend = | H13: 0
A14: change value | B14: =ROUND(B13*H3,0) -> -9641 | C14: =ROUND(C13*I3,0) -> 0 | D14: =ROUND(D13*J3,0) -> -9456 | E14: =ROUND(E13*K3,0) -> 29174 | G14: total div = | H14: ='20231107'!H14+H13 -> 4078.34
G15: buy charge= | H15: 11
A16: target return (monthly) (%) | B16: 1.75 | G16: sell charge&tax= | H16: ='20231107'!H15+64 -> 209
A17: risk(std) | B17: 4.94
A18: VaR(95%) | B18: -13474

Sheet 20240109
A1: (estimate) | B1: 2308 | C1: 2330 | D1: 2357 | E1: 2897 | G1: price | H1: 2308 | I1: 2330 | J1: 2357 | K1: 2897
A2: weight | B2: 0.19384871 | C2: 0.0054195645 | D2: 0.320514 | E2: 0.48021772 | G2: 45289 | H2: 313.5 | I2: 589.92 | J2: 489.5 | K2: 9.98 | L2: (reference price)
A3: value | B3: 38146 | C3: 1066 | D3: 63071 | E3: 94497 | G3: 45300 | H3: 306 | I3: 583 | J3: 461 | K3: 9.924328 | L3: (done price)
A4: total amount | B4: 121.67783 | C4: 1.8070345 | D4: 128.8478 | E4: 9468.6373 | G4: 45322 | H4: 280 | I4: 628 | J4: 445.5 | K4: 9.42 | L4: (observation price)
A5: last amount | B5: 118 | C5: 0 | D5: 160 | E5: 7161
A6: change | B6: 3.6778309 | C6: 1.8070345 | D6: -31.152196 | E6: 2307.6373 | G6: value | H6: 2308 | I6: 2330 | J6: 2357 | K6: 2897 | L6: Total Value | M6: Total Return | N6: Original Invest | O6: Return (%)
G7: 45289 | H7: =B5*H2 -> 36993 | I7: =C5*I2 -> 0 | J7: =D5*J2 -> 78320 | K7: =E5*K2 -> 71466.78 | L7: =SUM(H7:K7) -> 186779.78 | M7: ='20231207'!M9 -> 190649.12 | N7: ='20231207'!N8 -> 152401 | O7: =(M7/N7 - 1) * 100 -> 25.097027
A8: (real) | B8: 2308 | C8: 2330 | D8: 2357 | E8: 2897 | G8: 45300 | H8: =B11*H3 -> 37026 | I8: =C11*I3 -> 1166 | J8: =D11*J3 -> 59469 | K8: =E11*K3 -> 93973.462 | L8: =SUM(H8:K8) -> 191634.46 | M8: =L8+H14-H16 -> 195455.8 | N8: =ROUNDUP(N7+B13*H3+C13*I3+D13*J3+E13*K3, 0)+H15 -> 163110 | O8: =(M8/N8 - 1) * 100 -> 19.830668
A9: weight | B9: =B10/$L$8 -> 0.19321159 | C9: =C10/$L$8 -> 0.0060845006 | D9: =D10/$L$8 -> 0.31032519 | E9: =E10/$L$8 -> 0.49037872 | G9: 45322 | H9: =B11*H4 -> 33880 | I9: =C11*I4 -> 1256 | J9: =D11*J4 -> 57469.5 | K9: =E11*K4 -> 89197.98 | L9: =SUM(H9:K9) -> 181803.48 | M9: =L9+H14-H16 -> 185624.82 | N9: =N8 -> 163110 | O9: =(M9/N9 - 1) * 100 -> 13.803458
A10: value | B10: =B11*H3 -> 37026 | C10: =C11*I3 -> 1166 | D10: =D11*J3 -> 59469 | E10: =E11*K3 -> 93973.462
A11: total amount | B11: =B12+B13 -> 121 | C11: =C12+C13 -> 2 | D11: =D12+D13 -> 129 | E11: =E12+E13 -> 9469
A12: last amount | B12: 118 | C12: 0 | D12: 160 | E12: 7161 | G12: Note:
A13: change | B13: 3 | C13: 2 | D13: -31 | E13: 2308 | G13: dividend = | H13: 0
A14: change value | B14: =ROUND(B13*H3,0) -> 918 | C14: =ROUND(C13*I3,0) -> 1166 | D14: =ROUND(D13*J3,0) -> -14291 | E14: =ROUND(E13*K3,0) -> 22905 | G14: total div = | H14: ='20231207'!H14+H13 -> 4078.34
G15: buy charge= | H15: =7+3 -> 10
A16: target return (monthly) (%) | B16: 1.8 | G16: sell charge&tax= | H16: ='20231207'!H16+6+42 -> 257
A17: risk(std) | B17: 4.89
A18: VaR(95%) | B18: -15333

Sheet 20240205
A1: (estimate) | B1: 2308 | C1: 2330 | D1: 2357 | E1: 2897 | G1: price | H1: 2308 | I1: 2330 | J1: 2357 | K1: 2897
A2: weight | B2: 0.13332797 | C2: 0.11715327 | D2: 0.36478278 | E2: 0.38473599 | G2: 45322 | H2: 280 | I2: 628 | J2: 445.5 | K2: 9.42 | L2: (reference price)
A3: value | B3: 25573 | C3: 22470 | D3: 69967 | E3: 73794 | G3: 45327 | H3: 286 | I3: 645 | J3: 451 | K3: 9.392587 | L3: (done price)
A4: total amount | B4: 91.332143 | C4: 35.780255 | D4: 157.05275 | E4: 7833.758 | G4: 45351 | H4: 294.5 | I4: 690 | J4: 455 | K4: 9.95 | L4: (observation price)
A5: last amount | B5: 121 | C5: 2 | D5: 129 | E5: 9469
A6: change | B6: -29.667857 | C6: 33.780255 | D6: 28.05275 | E6: -1635.242 | G6: value | H6: 2308 | I6: 2330 | J6: 2357 | K6: 2897 | L6: Total Value | M6: Total Return | N6: Original Invest | O6: Return (%)
G7: 45322 | H7: =B5*H2 -> 33880 | I7: =C5*I2 -> 1256 | J7: =D5*J2 -> 57469.5 | K7: =E5*K2 -> 89197.98 | L7: =SUM(H7:K7) -> 181803.48 | M7: ='20240109'!M9 -> 185624.82 | N7: ='20240109'!N8 -> 163110 | O7: =(M7/N7 - 1) * 100 -> 13.803458
A8: (real) | B8: 2308 | C8: 2330 | D8: 2357 | E8: 2897 | G8: 45327 | H8: =B11*H3 -> 26026 | I8: =C11*I3 -> 23220 | J8: =D11*J3 -> 70807 | K8: =E11*K3 -> 73581.527 | L8: =SUM(H8:K8) -> 193634.53 | M8: =L8+H14-H16 -> 197378.87 | N8: =ROUNDUP(N7+B13*H3+C13*I3+D13*J3+E13*K3, 0)+H15 -> 173746 | O8: =(M8/N8 - 1) * 100 -> 13.601963
A9: weight | B9: =B10/$L$8 -> 0.13440785 | C9: =C10/$L$8 -> 0.11991663 | D9: =D10/$L$8 -> 0.36567342 | E9: =E10/$L$8 -> 0.3800021 | G9: 45351 | H9: =B11*H4 -> 26799.5 | I9: =C11*I4 -> 24840 | J9: =D11*J4 -> 71435 | K9: =E11*K4 -> 77948.3 | L9: =SUM(H9:K9) -> 201022.8 | M9: =L9+H14-H16 -> 204767.14 | N9: =N8 -> 173746 | O9: =(M9/N9 - 1) * 100 -> 17.854305
A10: value | B10: =B11*H3 -> 26026 | C10: =C11*I3 -> 23220 | D10: =D11*J3 -> 70807 | E10: =E11*K3 -> 73581.527
A11: total amount | B11: =B12+B13 -> 91 | C11: =C12+C13 -> 36 | D11: =D12+D13 -> 157 | E11: =E12+E13 -> 7834
A12: last amount | B12: 121 | C12: 2 | D12: 129 | E12: 9469 | G12: Note:
A13: change | B13: -30 | C13: 34 | D13: 28 | E13: -1635 | G13: dividend = | H13: 0
A14: change value | B14: =ROUND(B13*H3,0) -> -8580 | C14: =ROUND(C13*I3,0) -> 21930 | D14: =ROUND(D13*J3,0) -> 12628 | E14: =ROUND(E13*K3,0) -> -15357 | G14: total div = | H14: ='20240109'!H14+H13 -> 4078.34
G15: buy charge= | H15: =9+5 -> 14
A16: target return (monthly) (%) | B16: 1.75 | G16: sell charge&tax= | H16: ='20240109'!H16+8+69 -> 334
A17: risk(std) | B17: 5.15
A18: VaR(95%) | B18: -15990

Sheet 20240314
A1: (estimate) | B1: 2308 | C1: 2330 | D1: 2357 | E1: 2897 | G1: price | H1: 2308 | I1: 2330 | J1: 2357 | K1: 2897
A2: weight | B2: 0.11834114 | C2: 0.1165097 | D2: 0.33568389 | E2: 0.42946528 | G2: 45351 | H2: 294.5 | I2: 690 | J2: 455 | K2: 9.95 | L2: (reference price)
A3: value | B3: 24973 | C3: 24586 | D3: 70837 | E3: 90627 | G3: 45365 | H3: 310.5 | I3: 784 | J3: 431.5 | K3: 10.25 | L3: (done price)
A4: total amount | B4: 84.797963 | C4: 35.631884 | D4: 155.68571 | E4: 9108.2412 | G4: 45380 | H4: 342 | I4: 772.39 | J4: 425.5 | K4: 9.99 | L4: (observation price)
A5: last amount | B5: 91 | C5: 36 | D5: 157 | E5: 7834
A6: change | B6: -6.2020374 | C6: -0.36811594 | D6: -1.3142857 | E6: 1274.2412 | G6: value | H6: 2308 | I6: 2330 | J6: 2357 | K6: 2897 | L6: Total Value | M6: Total Return | N6: Original Invest | O6: Return (%)
G7: 45351 | H7: =B5*H2 -> 26799.5 | I7: =C5*I2 -> 24840 | J7: =D5*J2 -> 71435 | K7: =E5*K2 -> 77948.3 | L7: =SUM(H7:K7) -> 201022.8 | M7: ='20240205'!M9 -> 204767.14 | N7: ='20240205'!N8 -> 173746 | O7: =(M7/N7 - 1) * 100 -> 17.854305
A8: (real) | B8: 2308 | C8: 2330 | D8: 2357 | E8: 2897 | G8: 45365 | H8: =B11*H3 -> 26392.5 | I8: =C11*I3 -> 28224 | J8: =D11*J3 -> 67314 | K8: =E11*K3 -> 93357 | L8: =SUM(H8:K8) -> 215287.5 | M8: =L8+H14-H16 -> 219143.84 | N8: =ROUNDUP(N7+B13*H3+C13*I3+D13*J3+E13*K3, 0)+H15 -> 184514 | O8: =(M8/N8 - 1) * 100 -> 18.768137
A9: weight | B9: =B10/$L$8 -> 0.12259188 | C9: =C10/$L$8 -> 0.13109911 | D9: =D10/$L$8 -> 0.31267027 | E9: =E10/$L$8 -> 0.43363874 | G9: 45380 | H9: =B11*H4 -> 29070 | I9: =C11*I4 -> 27806.04 | J9: =D11*J4 -> 66378 | K9: =E11*K4 -> 90988.92 | L9: =SUM(H9:K9) -> 214242.96 | M9: =L9+H14-H16 -> 218099.3 | N9: =N8 -> 184514 | O9: =(M9/N9 - 1) * 100 -> 18.202033
A10: value | B10: =B11*H3 -> 26392.5 | C10: =C11*I3 -> 28224 | D10: =D11*J3 -> 67314 | E10: =E11*K3 -> 93357
A11: total amount | B11: =B12+B13 -> 85 | C11: =C12+C13 -> 36 | D11: =D12+D13 -> 156 | E11: =E12+E13 -> 9108
A12: last amount | B12: 91 | C12: 36 | D12: 157 | E12: 7834 | G12: Note: 3/18 2330 dividend $3.5
A13: change | B13: -6 | C13: 0 | D13: -1 | E13: 1274 | G13: dividend = | H13: 120
A14: change value | B14: =ROUND(B13*H3,0) -> -1863 | C14: =ROUND(C13*I3,0) -> 0 | D14: =ROUND(D13*J3,0) -> -432 | E14: =ROUND(E13*K3,0) -> 13059 | G14: total div = | H14: ='20240205'!H14+H13 -> 4198.34
G15: buy charge= | H15: 4
A16: target return (monthly) (%) | B16: 1.75 | G16: sell charge&tax= | H16: ='20240205'!H16+2+6 -> 342
A17: risk(std) | B17: 5.02
A18: VaR(95%) | B18: -17073

Sheet 20240409
A1: (estimate) | B1: 2308 | C1: 2330 | D1: 2357 | E1: 2897 | G1: price | H1: 2308 | I1: 2330 | J1: 2357 | K1: 2897
A2: weight | B2: 0.14525466 | C2: 0.11820545 | D2: 0.31215356 | E2: 0.42438634 | G2: 45380 | H2: 342 | I2: 772.39 | J2: 425.5 | K2: 9.99 | L2: (reference price)
A3: value | B3: 32572 | C3: 26507 | D3: 69998 | E3: 95166 | G3: 45391 | H3: 334 | I3: 799 | J3: 425.5 | K3: 10 | L3: (done price)
A4: total amount | B4: 95.239766 | C4: 34.318019 | D4: 164.50764 | E4: 9526.1261 | G4: 45412 | H4: 320.5 | I4: 790 | J4: 430 | K4: 9.98 | L4: (observation price)
A5: last amount | B5: 85 | C5: 36 | D5: 156 | E5: 9108
A6: change | B6: 10.239766 | C6: -1.6819809 | D6: 8.5076381 | E6: 418.12613 | G6: value | H6: 2308 | I6: 2330 | J6: 2357 | K6: 2897 | L6: Total Value | M6: Total Return | N6: Original Invest | O6: Return (%)
G7: 45380 | H7: =B5*H2 -> 29070 | I7: =C5*I2 -> 27806.04 | J7: =D5*J2 -> 66378 | K7: =E5*K2 -> 90988.92 | L7: =SUM(H7:K7) -> 214242.96 | M7: ='20240314'!M9 -> 218099.3 | N7: ='20240314'!N8 -> 184514 | O7: =(M7/N7 - 1) * 100 -> 18.202033
A8: (real) | B8: 2308 | C8: 2330 | D8: 2357 | E8: 2897 | G8: 45391 | H8: =B11*H3 -> 31730 | I8: =C11*I3 -> 27166 | J8: =D11*J3 -> 70207.5 | K8: =E11*K3 -> 95260 | L8: =SUM(H8:K8) -> 224363.5 | M8: =L8+H14-H16 -> 228214.84 | N8: =ROUNDUP(N7+B13*H3+C13*I3+D13*J3+E13*K3, 0)+H15 -> 194269 | O8: =(M8/N8 - 1) * 100 -> 17.473627
A9: weight | B9: =B10/$L$8 -> 0.14142229 | C9: =C10/$L$8 -> 0.1210803 | D9: =D10/$L$8 -> 0.31291855 | E9: =E10/$L$8 -> 0.42457886 | G9: 45412 | H9: =B11*H4 -> 30447.5 | I9: =C11*I4 -> 26860 | J9: =D11*J4 -> 70950 | K9: =E11*K4 -> 95069.48 | L9: =SUM(H9:K9) -> 223326.98 | M9: =L9+H14-H16 -> 227178.32 | N9: =N8 -> 194269 | O9: =(M9/N9 - 1) * 100 -> 16.940078
A10: value | B10: =B11*H3 -> 31730 | C10: =C11*I3 -> 27166 | D10: =D11*J3 -> 70207.5 | E10: =E11*K3 -> 95260
A11: total amount | B11: =B12+B13 -> 95 | C11: =C12+C13 -> 34 | D11: =D12+D13 -> 165 | E11: =E12+E13 -> 9526
A12: last amount | B12: 85 | C12: 36 | D12: 156 | E12: 9108 | G12: Note:
A13: change | B13: 10 | C13: -2 | D13: 9 | E13: 418 | G13: dividend = | H13: 0
A14: change value | B14: =ROUND(B13*H3,0) -> 3340 | C14: =ROUND(C13*I3,0) -> -1598 | D14: =ROUND(D13*J3,0) -> 3830 | E14: =ROUND(E13*K3,0) -> 4180 | G14: total div = | H14: ='20240314'!H14+H13 -> 4198.34
G15: buy charge= | H15: 3
A16: target return (monthly) (%) | B16: 1.75 | G16: sell charge&tax= | H16: ='20240314'!H16+5 -> 347
A17: risk(std) | B17: 4.97
A18: VaR(95%) | B18: -17973

Sheet 20240507
A1: (estimate) | B1: 2308 | C1: 2330 | D1: 2357 | E1: 2897 | G1: price | H1: 2308 | I1: 2330 | J1: 2357 | K1: 2897
A2: weight | B2: 0.11967762 | C2: 0.15164338 | D2: 0.32841802 | E2: 0.40026097 | G2: 45412 | H2: 320.5 | I2: 790 | J2: 430 | K2: 9.98 | L2: (reference price)
A3: value | B3: 27924 | C3: 35382 | D3: 76629 | E3: 93392 | G3: 45419 | H3: 324 | I3: 798 | J3: 458.5 | K3: 10.15 | L3: (done price)
A4: total amount | B4: 87.126365 | C4: 44.787342 | D4: 178.20698 | E4: 9357.9158 | G4: 45443 | H4: 325 | I4: 821 | J4: 513 | K4: 10.5 | L4: (observation price)
A5: last amount | B5: 95 | C5: 34 | D5: 165 | E5: 9526
A6: change | B6: -7.8736349 | C6: 10.787342 | D6: 13.206977 | E6: -168.08417 | G6: value | H6: 2308 | I6: 2330 | J6: 2357 | K6: 2897 | L6: Total Value | M6: Total Return | N6: Original Invest | O6: Return (%)
G7: 45412 | H7: =B5*H2 -> 30447.5 | I7: =C5*I2 -> 26860 | J7: =D5*J2 -> 70950 | K7: =E5*K2 -> 95069.48 | L7: =SUM(H7:K7) -> 223326.98 | M7: ='20240409'!M9 -> 227178.32 | N7: ='20240409'!N8 -> 194269 | O7: =(M7/N7 - 1) * 100 -> 16.940078
A8: (real) | B8: 2308 | C8: 2330 | D8: 2357 | E8: 2897 | G8: 45419 | H8: =B11*H3 -> 28188 | I8: =C11*I3 -> 35910 | J8: =D11*J3 -> 81613 | K8: =E11*K3 -> 94983.7 | L8: =SUM(H8:K8) -> 240694.7 | M8: =L8+H14-H16 -> 244532.04 | N8: =ROUNDUP(N7+B13*H3+C13*I3+D13*J3+E13*K3, 0)+H15 -> 204716 | O8: =(M8/N8 - 1) * 100 -> 19.449403
A9: weight | B9: =B10/$L$8 -> 0.11711101 | C9: =C10/$L$8 -> 0.14919315 | D9: =D10/$L$8 -> 0.33907269 | E9: =E10/$L$8 -> 0.39462315 | G9: 45443 | H9: =B11*H4 -> 28275 | I9: =C11*I4 -> 36945 | J9: =D11*J4 -> 91314 | K9: =E11*K4 -> 98259 | L9: =SUM(H9:K9) -> 254793 | M9: =L9+H14-H16 -> 258630.34 | N9: =N8 -> 204716 | O9: =(M9/N9 - 1) * 100 -> 26.336163
A10: value | B10: =B11*H3 -> 28188 | C10: =C11*I3 -> 35910 | D10: =D11*J3 -> 81613 | E10: =E11*K3 -> 94983.7
A11: total amount | B11: =B12+B13 -> 87 | C11: =C12+C13 -> 45 | D11: =D12+D13 -> 178 | E11: =E12+E13 -> 9358
A12: last amount | B12: =B5 -> 95 | C12: =C5 -> 34 | D12: =D5 -> 165 | E12: =E5 -> 9526 | G12: Note:
A13: change | B13: =ROUND(B6, 0) -> -8 | C13: =ROUND(C6, 0) -> 11 | D13: =ROUND(D6, 0) -> 13 | E13: =ROUND(E6, 0) -> -168 | G13: dividend = | H13: 0
A14: change value | B14: =ROUND(B13*H3,0) -> -2592 | C14: =ROUND(C13*I3,0) -> 8778 | D14: =ROUND(D13*J3,0) -> 5961 | E14: =ROUND(E13*K3,0) -> -1705 | G14: total div = | H14: ='20240409'!H14+H13 -> 4198.34
G15: buy charge= | H15: 5
A16: target return (monthly) (%) | B16: 1.75 | G16: sell charge&tax= | H16: ='20240409'!H16+14 -> 361
A17: risk(std) | B17: 4.98
A18: VaR(95%) | B18: -18710

Sheet 20240607
A1: (estimate) | B1: 2308 | C1: 2330 | D1: 2357 | E1: 2897 | G1: price | H1: 2308 | I1: 2330 | J1: 2357 | K1: 2897
A2: weight | B2: 0.11369211 | C2: 0.13144377 | D2: 0.2966848 | E2: 0.45817933 | G2: 45443 | H2: 325 | I2: 821 | J2: 513 | K2: 10.5 | L2: (reference price)
A3: value | B3: 30105 | C3: 34805 | D3: 78560 | E3: 121323 | G3: 45450 | H3: 343.5 | I3: 881 | J3: 493 | K3: 10.733341 | L3: (done price)
A4: total amount | B4: 92.630769 | C4: 42.393423 | D4: 153.1384 | E4: 11554.571 | G4: 45471 | H4: 387.5 | I4: 966 | J4: 498 | K4: 10.5 | L4: (observation price)
A5: last amount | B5: 87 | C5: 45 | D5: 178 | E5: 9358
A6: change | B6: 5.6307692 | C6: -2.6065773 | D6: -24.861598 | E6: 2196.5714 | G6: value | H6: 2308 | I6: 2330 | J6: 2357 | K6: 2897 | L6: Total Value | M6: Total Return | N6: Original Invest | O6: Return (%)
G7: 45443 | H7: =B5*H2 -> 28275 | I7: =C5*I2 -> 36945 | J7: =D5*J2 -> 91314 | K7: =E5*K2 -> 98259 | L7: =SUM(H7:K7) -> 254793 | M7: ='20240507'!M9 -> 258630.34 | N7: ='20240507'!N8 -> 204716 | O7: =(M7/N7 - 1) * 100 -> 26.336163
A8: (real) | B8: 2308 | C8: 2330 | D8: 2357 | E8: 2897 | G8: 45450 | H8: =B11*H3 -> 31945.5 | I8: =C11*I3 -> 37002 | J8: =D11*J3 -> 75429 | K8: =E11*K3 -> 124023.76 | L8: =SUM(H8:K8) -> 268400.26 | M8: =L8+H14-H16 -> 272902.6 | N8: =ROUNDUP(N7+B13*H3+C13*I3+D13*J3+E13*K3, 0)+H15 -> 215426 | O8: =(M8/N8 - 1) * 100 -> 26.680436
A9: weight | B9: =B10/$L$8 -> 0.11902187 | C9: =C10/$L$8 -> 0.13786127 | D9: =D10/$L$8 -> 0.28103177 | E9: =E10/$L$8 -> 0.46208509 | G9: 45471 | H9: =B11*H4 -> 36037.5 | I9: =C11*I4 -> 40572 | J9: =D11*J4 -> 76194 | K9: =E11*K4 -> 121327.5 | L9: =SUM(H9:K9) -> 274131 | M9: =L9+H14-H16 -> 278633.34 | N9: =N8 -> 215426 | O9: =(M9/N9 - 1) * 100 -> 29.340627
A10: value | B10: =B11*H3 -> 31945.5 | C10: =C11*I3 -> 37002 | D10: =D11*J3 -> 75429 | E10: =E11*K3 -> 124023.76
A11: total amount | B11: =B12+B13 -> 93 | C11: =C12+C13 -> 42 | D11: =D12+D13 -> 153 | E11: =E12+E13 -> 11555
A12: last amount | B12: =B5 -> 87 | C12: =C5 -> 45 | D12: =D5 -> 178 | E12: =E5 -> 9358 | G12: Note: 6/18 2308 dividend $6.43, 6/13 2330 dividend $3.5
A13: change | B13: =ROUND(B6, 0) -> 6 | C13: =ROUND(C6, 0) -> -3 | D13: =ROUND(D6, 0) -> -25 | E13: =ROUND(E6, 0) -> 2197 | G13: dividend = | H13: =587+141 -> 728
A14: change value | B14: =ROUND(B13*H3,0) -> 2061 | C14: =ROUND(C13*I3,0) -> -2643 | D14: =ROUND(D13*J3,0) -> -12325 | E14: =ROUND(E13*K3,0) -> 23581 | G14: total div = | H14: ='20240507'!H14+H13 -> 4926.34
G15: buy charge= | H15: 35
A16: target return (monthly) (%) | B16: 1.8 | G16: sell charge&tax= | H16: ='20240507'!H16+63 -> 424
A17: risk(std) | B17: 4.93
A18: VaR(95%) | B18: -20841

Sheet 20240708
A1: (estimate) | B1: 2308 | C1: 2330 | D1: 2357 | E1: 2897 | G1: price | H1: 2308 | I1: 2330 | J1: 2357 | K1: 2897
A2: weight | B2: 0.12522024 | C2: 0.13684852 | D2: 0.29080377 | E2: 0.44712748 | G2: 45471 | H2: 387.5 | I2: 966 | J2: 498 | K2: 10.5 | L2: (reference price)
A3: value | B3: 35477 | C3: 38771 | D3: 82390 | E3: 126679 | G3: 45481 | H3: 402 | I3: 1045 | J3: 486 | K3: 10.9 | L3: (done price)
A4: total amount | B4: 93.257082 | C4: 40.290736 | D4: 165.44177 | E4: 12064.667 | G4: 45504 | H4: 414.5 | I4: 934 | J4: 456 | K4: 10.2 | L4: (observation price)
A5: last amount | B5: 93 | C5: 42 | D5: 153 | E5: 11555
A6: change | B6: 0.25708237 | C6: -1.7092641 | D6: 12.441767 | E6: 509.66667 | G6: value | H6: 2308 | I6: 2330 | J6: 2357 | K6: 2897 | L6: Total Value | M6: Total Return | N6: Original Invest | O6: Return (%)
G7: 45471 | H7: =B5*H2 -> 36037.5 | I7: =C5*I2 -> 40572 | J7: =D5*J2 -> 76194 | K7: =E5*K2 -> 121327.5 | L7: =SUM(H7:K7) -> 274131 | M7: ='20240607'!M9 -> 278633.34 | N7: ='20240607'!N8 -> 215426 | O7: =(M7/N7 - 1) * 100 -> 29.340627
A8: (real) | B8: 2308 | C8: 2330 | D8: 2357 | E8: 2897 | G8: 45481 | H8: =B11*H3 -> 37386 | I8: =C11*I3 -> 41800 | J8: =D11*J3 -> 80190 | K8: =E11*K3 -> 131508.5 | L8: =SUM(H8:K8) -> 290884.5 | M8: =L8+H14-H16 -> 303282.84 | N8: =ROUNDUP(N7+B13*H3+C13*I3+D13*J3+E13*K3, 0)+H15 -> 224742 | O8: =(M8/N8 - 1) * 100 -> 34.947113
A9: weight | B9: =B10/$L$8 -> 0.12852524 | C9: =C10/$L$8 -> 0.14369965 | D9: =D10/$L$8 -> 0.27567643 | E9: =E10/$L$8 -> 0.45209869 | G9: 45504 | H9: =B11*H4 -> 38548.5 | I9: =C11*I4 -> 37360 | J9: =D11*J4 -> 75240 | K9: =E11*K4 -> 123063 | L9: =SUM(H9:K9) -> 274211.5 | M9: =L9+H14-H16 -> 286609.84 | N9: =N8 -> 224742 | O9: =(M9/N9 - 1) * 100 -> 27.528384
A10: value | B10: =B11*H3 -> 37386 | C10: =C11*I3 -> 41800 | D10: =D11*J3 -> 80190 | E10: =E11*K3 -> 131508.5
A11: total amount | B11: =B12+B13 -> 93 | C11: =C12+C13 -> 40 | D11: =D12+D13 -> 165 | E11: =E12+E13 -> 12065
A12: last amount | B12: =B5 -> 93 | C12: =C5 -> 42 | D12: =D5 -> 153 | E12: =E5 -> 11555 | G12: Note: 7/2 2357 dividend $17, 7/24 2897 dividend $0.44
A13: change | B13: =ROUND(B6, 0) -> 0 | C13: =ROUND(C6, 0) -> -2 | D13: =ROUND(D6, 0) -> 12 | E13: =ROUND(E6, 0) -> 510 | G13: dividend = | H13: =2591+5313 -> 7904
A14: change value | B14: =ROUND(B13*H3,0) -> 0 | C14: =ROUND(C13*I3,0) -> -2090 | D14: =ROUND(D13*J3,0) -> 5832 | E14: =ROUND(E13*K3,0) -> 5559 | G14: total div = | H14: ='20240607'!H14+H13 -> 12830.34
G15: buy charge= | H15: 15
A16: target return (monthly) (%) | B16: 1.85 | G16: sell charge&tax= | H16: ='20240607'!H16+8 -> 432
A17: risk(std) | B17: 4.91
A18: VaR(95%) | B18: -22029

Sheet 20240807
A1: (estimate) | B1: 2308 | C1: 2330 | D1: 2357 | E1: 2897 | G1: price | H1: 2308 | I1: 2330 | J1: 2357 | K1: 2897
A2: weight | B2: 0.18286587 | C2: 0.10895489 | D2: 0.28131572 | E2: 0.42686351 | G2: 45504 | H2: 414.5 | I2: 934 | J2: 456 | K2: 10.2 | L2: (reference price)
A3: value | B3: 51495 | C3: 30682 | D3: 79219 | E3: 120205 | G3: 45511 | H3: 384.5 | I3: 898 | J3: 462 | K3: 9.8 | L3: (done price)
A4: total amount | B4: 124.23402 | C4: 32.850107 | D4: 179.96972 | E4: 11784.804 | G4: 45534 | H4: 399.5 | I4: 944 | J4: 537 | K4: 10.3 | L4: (observation price)
A5: last amount | B5: 93 | C5: 40 | D5: 165 | E5: 12065
A6: change | B6: 31.234017 | C6: -7.1498929 | D6: 14.969723 | E6: -280.19608 | G6: value | H6: 2308 | I6: 2330 | J6: 2357 | K6: 2897 | L6: Total Value | M6: Total Return | N6: Original Invest | O6: Return (%)
G7: 45471 | H7: =B5*H2 -> 38548.5 | I7: =C5*I2 -> 37360 | J7: =D5*J2 -> 75240 | K7: =E5*K2 -> 123063 | L7: =SUM(H7:K7) -> 274211.5 | M7: ='20240708'!M9 -> 286609.84 | N7: ='20240708'!N8 -> 224742 | O7: =(M7/N7 - 1) * 100 -> 27.528384
A8: (real) | B8: 2308 | C8: 2330 | D8: 2357 | E8: 2897 | G8: 45481 | H8: =B11*H3 -> 47678 | I8: =C11*I3 -> 29634 | J8: =D11*J3 -> 83160 | K8: =E11*K3 -> 115493 | L8: =SUM(H8:K8) -> 275965 | M8: =L8+H14-H16 -> 288326.34 | N8: =ROUNDUP(N7+B13*H3+C13*I3+D13*J3+E13*K3, 0)+H15 -> 234587 | O8: =(M8/N8 - 1) * 100 -> 22.908064
A9: weight | B9: =B10/$L$8 -> 0.17276829 | C9: =C10/$L$8 -> 0.10738318 | D9: =D10/$L$8 -> 0.30134256 | E9: =E10/$L$8 -> 0.41850597 | G9: 45504 | H9: =B11*H4 -> 49538 | I9: =C11*I4 -> 31152 | J9: =D11*J4 -> 96660 | K9: =E11*K4 -> 121385.5 | L9: =SUM(H9:K9) -> 298735.5 | M9: =L9+H14-H16 -> 311096.84 | N9: =N8 -> 234587 | O9: =(M9/N9 - 1) * 100 -> 32.614697
A10: value | B10: =B11*H3 -> 47678 | C10: =C11*I3 -> 29634 | D10: =D11*J3 -> 83160 | E10: =E11*K3 -> 115493
A11: total amount | B11: =B12+B13 -> 124 | C11: =C12+C13 -> 33 | D11: =D12+D13 -> 180 | E11: =E12+E13 -> 11785
A12: last amount | B12: =B5 -> 93 | C12: =C5 -> 40 | D12: =D5 -> 165 | E12: =E5 -> 12065 | G12: Note:
A13: change | B13: =ROUND(B6, 0) -> 31 | C13: =ROUND(C6, 0) -> -7 | D13: =ROUND(D6, 0) -> 15 | E13: =ROUND(E6, 0) -> -280 | G13: dividend = | H13: 0
A14: change value | B14: =ROUND(B13*H3,0) -> 11920 | C14: =ROUND(C13*I3,0) -> -6286 | D14: =ROUND(D13*J3,0) -> 6930 | E14: =ROUND(E13*K3,0) -> -2744 | G14: total div = | H14: ='20240708'!H14+H13 -> 12830.34
G15: buy charge= | H15: 25
A16: target return (monthly) (%) | B16: 1.8 | G16: sell charge&tax= | H16: ='20240708'!H16+11+26 -> 469
A17: risk(std) | B17: 4.93
A18: VaR(95%) | B18: -22168

Sheet 20240909
A1: (estimate) | B1: 2308 | C1: 2330 | D1: 2357 | E1: 2897 | G1: price | H1: 2308 | I1: 2330 | J1: 2357 | K1: 2897
A2: weight | B2: 0.17511645 | C2: 0.10032187 | D2: 0.26270402 | E2: 0.46185766 | G2: 45534 | H2: 399.5 | I2: 944 | J2: 537 | K2: 10.3 | L2: (reference price)
A3: value | B3: 54065 | C3: 30973 | D3: 81106 | E3: 142592 | G3: 45544 | H3: 366 | I3: 899 | J3: 527 | K3: =(10.1*686+10*858+10.1*515)/2059 -> 10.058329 | L3: (done price)
A4: total amount | B4: 135.33166 | C4: 32.810381 | D4: 151.03538 | E4: 13843.883 | G4: 45565 | H4: 380.5 | I4: 957 | J4: 553 | K4: 10.05 | L4: (observation price)
A5: last amount | B5: 124 | C5: 33 | D5: 180 | E5: 11785
A6: change | B6: 11.331665 | C6: -0.18961864 | D6: -28.964618 | E6: 2058.8835 | G6: value | H6: 2308 | I6: 2330 | J6: 2357 | K6: 2897 | L6: Total Value | M6: Total Return | N6: Original Invest | O6: Return (%)
G7: 45534 | H7: =B5*H2 -> 49538 | I7: =C5*I2 -> 31152 | J7: =D5*J2 -> 96660 | K7: =E5*K2 -> 121385.5 | L7: =SUM(H7:K7) -> 298735.5 | M7: ='20240807'!M9 -> 311096.84 | N7: ='20240807'!N8 -> 234587 | O7: =(M7/N7 - 1) * 100 -> 32.614697
A8: (real) | B8: 2308 | C8: 2330 | D8: 2357 | E8: 2897 | G8: 45544 | H8: =B11*H3 -> 49410 | I8: =C11*I3 -> 29667 | J8: =D11*J3 -> 79577 | K8: =E11*K3 -> 139247.51 | L8: =SUM(H8:K8) -> 297901.51 | M8: =L8+H14-H16 -> 310328.85 | N8: =ROUNDUP(N7+B13*H3+C13*I3+D13*J3+E13*K3, 0)+H15 -> 244073 | O8: =(M8/N8 - 1) * 100 -> 27.145916
A9: weight | B9: =B10/$L$8 -> 0.16586019 | C9: =C10/$L$8 -> 0.099586605 | D9: =D10/$L$8 -> 0.2671252 | E9: =E10/$L$8 -> 0.46742801 | G9: 45565 | H9: =B11*H4 -> 51367.5 | I9: =C11*I4 -> 31581 | J9: =D11*J4 -> 83503 | K9: =E11*K4 -> 139132.2 | L9: =SUM(H9:K9) -> 305583.7 | M9: =L9+H14-H16 -> 318011.04 | N9: =N8 -> 244073 | O9: =(M9/N9 - 1) * 100 -> 30.293412
A10: value | B10: =B11*H3 -> 49410 | C10: =C11*I3 -> 29667 | D10: =D11*J3 -> 79577 | E10: =E11*K3 -> 139247.51
A11: total amount | B11: =B12+B13 -> 135 | C11: =C12+C13 -> 33 | D11: =D12+D13 -> 151 | E11: =E12+E13 -> 13844
A12: last amount | B12: =B5 -> 124 | C12: =C5 -> 33 | D12: =D5 -> 180 | E12: =E5 -> 11785 | G12: Note: 9/12 2330 dividend $4
A13: change | B13: =ROUND(B6, 0) -> 11 | C13: =ROUND(C6, 0) -> 0 | D13: =ROUND(D6, 0) -> -29 | E13: =ROUND(E6, 0) -> 2059 | G13: dividend = | H13: =4*C11 -> 132
A14: change value | B14: =ROUND(B13*H3,0) -> 4026 | C14: =ROUND(C13*I3,0) -> 0 | D14: =ROUND(D13*J3,0) -> -15283 | E14: =ROUND(E13*K3,0) -> 20710 | G14: total div = | H14: ='20240807'!H14+H13 -> 12962.34
G15: buy charge= | H15: =25+7 -> 32
A16: target return (monthly) (%) | B16: 1.85 | G16: sell charge&tax= | H16: ='20240807'!H16+21+45 -> 535
A17: risk(std) | B17: 4.9
A18: VaR(95%) | B18: -23941

Sheet 20241008
A1: (estimate) | B1: 2308 | C1: 2330 | D1: 2357 | E1: 2897 | G1: price | H1: 2308 | I1: 2330 | J1: 2357 | K1: 2897
A2: weight | B2: 0.16420424 | C2: 0.12115613 | D2: 0.28080477 | E2: 0.43383486 | G2: 45565 | H2: 380.5 | I2: 957 | J2: 553 | K2: 10.05 | L2: (reference price)
A3: value | B3: 51797 | C3: 38218 | D3: 88578 | E3: 136850 | G3: 45573 | H3: 372.5 | I3: 999 | J3: 575 | K3: 10.05 | L3: (done price)
A4: total amount | B4: 136.12878 | C4: 40.113356 | D4: 160.17722 | E4: 13616.915 | G4: 45595 | H4: 404 | I4: 1030 | J4: 575 | K4: 9.83 | L4: (observation price)
A5: last amount | B5: 135 | C5: 33 | D5: 151 | E5: 13844
A6: change | B6: 1.1287779 | C6: 7.1133561 | D6: 9.1772152 | E6: -227.08458 | G6: value | H6: 2308 | I6: 2330 | J6: 2357 | K6: 2897 | L6: Total Value | M6: Total Return | N6: Original Invest | O6: Return (%)
G7: 45565 | H7: =B5*H2 -> 51367.5 | I7: =C5*I2 -> 31581 | J7: =D5*J2 -> 83503 | K7: =E5*K2 -> 139132.2 | L7: =SUM(H7:K7) -> 305583.7 | M7: ='20240909'!M9 -> 318011.04 | N7: ='20240909'!N8 -> 244073 | O7: =(M7/N7 - 1) * 100 -> 30.293412
A8: (real) | B8: 2308 | C8: 2330 | D8: 2357 | E8: 2897 | G8: 45573 | H8: =B11*H3 -> 50660 | I8: =C11*I3 -> 39960 | J8: =D11*J3 -> 92000 | K8: =E11*K3 -> 136850.85 | L8: =SUM(H8:K8) -> 319470.85 | M8: =L8+H14-H16 -> 331889.19 | N8: =ROUNDUP(N7+B13*H3+C13*I3+D13*J3+E13*K3, 0)+H15 -> 254350 | O8: =(M8/N8 - 1) * 100 -> 30.485233
A9: weight | B9: =B10/$L$8 -> 0.15857472 | C9: =C10/$L$8 -> 0.12508183 | D9: =D10/$L$8 -> 0.2879762 | E9: =E10/$L$8 -> 0.42836725 | G9: 45595 | H9: =B11*H4 -> 54944 | I9: =C11*I4 -> 41200 | J9: =D11*J4 -> 92000 | K9: =E11*K4 -> 133855.11 | L9: =SUM(H9:K9) -> 321999.11 | M9: =L9+H14-H16 -> 334417.45 | N9: =N8 -> 254350 | O9: =(M9/N9 - 1) * 100 -> 31.479241
A10: value | B10: =B11*H3 -> 50660 | C10: =C11*I3 -> 39960 | D10: =D11*J3 -> 92000 | E10: =E11*K3 -> 136850.85
A11: total amount | B11: =B12+B13 -> 136 | C11: =C12+C13 -> 40 | D11: =D12+D13 -> 160 | E11: =E12+E13 -> 13617
A12: last amount | B12: 135 | C12: 33 | D12: 151 | E12: 13844 | G12: Note:
A13: change | B13: =ROUND(B6, 0) -> 1 | C13: =ROUND(C6, 0) -> 7 | D13: =ROUND(D6, 0) -> 9 | E13: =ROUND(E6, 0) -> -227 | G13: dividend =
A14: change value | B14: =ROUND(B13*H3,0) -> 373 | C14: =ROUND(C13*I3,0) -> 6993 | D14: =ROUND(D13*J3,0) -> 5175 | E14: =ROUND(E13*K3,0) -> -2281 | G14: total div = | H14: ='20240909'!H14+H13 -> 12962.34
G15: buy charge= | H15: 17
A16: target return (monthly) (%) | B16: 1.85 | G16: sell charge&tax= | H16: ='20240909'!H16+9 -> 544
A17: risk(std) | B17: 4.92
A18: VaR(95%) | B18: -24572

Sheet 20241107
A1: (estimate) | B1: 2308 | C1: 2330 | D1: 2357 | E1: 2897 | G1: price | H1: 2308 | I1: 2330 | J1: 2357 | K1: 2897
A2: weight | B2: 0.16942618 | C2: 0.1322015 | D2: 0.29073123 | E2: 0.40764108 | G2: 45595 | H2: 404 | I2: 1030 | J2: 575 | K2: 9.83 | L2: (reference price)
A3: value | B3: 56249 | C3: 43891 | D3: 96523 | E3: 135336 | G3: 45603 | H3: 401.5 | I3: 1055 | J3: 606 | K3: 9.84 | L3: (done price)
A4: total amount | B4: 139.2302 | C4: 42.612621 | D4: 167.86609 | E4: 13767.65 | G4: 45625 | H4: 381 | I4: 996 | J4: 588 | K4: 9.86 | L4: (observation price)
A5: last amount | B5: 136 | C5: 40 | D5: 160 | E5: 13617
A6: change | B6: 3.230198 | C6: 2.6126214 | D6: 7.866087 | E6: 150.65005 | G6: value | H6: 2308 | I6: 2330 | J6: 2357 | K6: 2897 | L6: Total Value | M6: Total Return | N6: Original Invest | O6: Return (%)
G7: 45595 | H7: =B5*H2 -> 54944 | I7: =C5*I2 -> 41200 | J7: =D5*J2 -> 92000 | K7: =E5*K2 -> 133855.11 | L7: =SUM(H7:K7) -> 321999.11 | M7: ='20241008'!M9 -> 334417.45 | N7: ='20241008'!N8 -> 254350 | O7: =(M7/N7 - 1) * 100 -> 31.479241
A8: (real) | B8: 2308 | C8: 2330 | D8: 2357 | E8: 2897 | G8: 45603 | H8: =B11*H3 -> 55808.5 | I8: =C11*I3 -> 45365 | J8: =D11*J3 -> 101808 | K8: =E11*K3 -> 135477.12 | L8: =SUM(H8:K8) -> 338458.62 | M8: =L8+H14-H16 -> 350876.96 | N8: =ROUNDUP(N7+B13*H3+C13*I3+D13*J3+E13*K3, 0)+H15 -> 265067 | O8: =(M8/N8 - 1) * 100 -> 32.372932
A9: weight | B9: =B10/$L$8 -> 0.16489017 | C9: =C10/$L$8 -> 0.13403411 | D9: =D10/$L$8 -> 0.30079896 | E9: =E10/$L$8 -> 0.40027676 | G9: 45625 | H9: =B11*H4 -> 52959 | I9: =C11*I4 -> 42828 | J9: =D11*J4 -> 98784 | K9: =E11*K4 -> 135752.48 | L9: =SUM(H9:K9) -> 330323.48 | M9: =L9+H14-H16 -> 342741.82 | N9: =N8 -> 265067 | O9: =(M9/N9 - 1) * 100 -> 29.303844
A10: value | B10: =B11*H3 -> 55808.5 | C10: =C11*I3 -> 45365 | D10: =D11*J3 -> 101808 | E10: =E11*K3 -> 135477.12
A11: total amount | B11: =B12+B13 -> 139 | C11: =C12+C13 -> 43 | D11: =D12+D13 -> 168 | E11: =E12+E13 -> 13768
A12: last amount | B12: 136 | C12: 40 | D12: 160 | E12: 13617 | G12: Note:
A13: change | B13: =ROUND(B6, 0) -> 3 | C13: =ROUND(C6, 0) -> 3 | D13: =ROUND(D6, 0) -> 8 | E13: =ROUND(E6, 0) -> 151 | G13: dividend =
A14: change value | B14: =ROUND(B13*H3,0) -> 1205 | C14: =ROUND(C13*I3,0) -> 3165 | D14: =ROUND(D13*J3,0) -> 4848 | E14: =ROUND(E13*K3,0) -> 1486 | G14: total div = | H14: ='20241008'!H14+H13 -> 12962.34
G15: buy charge= | H15: 13
A16: target return (monthly) (%) | B16: 1.9 | G16: sell charge&tax= | H16: ='20241008'!H16 -> 544
A17: risk(std) | B17: 4.92
A18: VaR(95%) | B18: -25729

Sheet 20241209
A1: (estimate) | B1: 2308 | C1: 2330 | D1: 2357 | E1: 2897 | G1: price | H1: 2308 | I1: 2330 | J1: 2357 | K1: 2897
A2: weight | B2: 0.1622161 | C2: 0.14251701 | D2: 0.30996209 | E2: 0.3853048 | G2: 45625 | H2: 381 | I2: 996 | J2: 588 | K2: 9.86 | L2: (reference price)
A3: value | B3: 55206 | C3: 48502 | D3: 105487 | E3: 131128 | G3: 45635 | H3: 399 | I3: 1070 | J3: 604 | K3: 9.93 | L3: (done price)
A4: total amount | B4: 144.89764 | C4: 48.696787 | D4: 179.39966 | E4: 13298.986 | G4: 45657 | H4: 430.5 | I4: 1075 | J4: 616 | K4: 9.89 | L4: (observation price)
A5: last amount | B5: 139 | C5: 43 | D5: 168 | E5: 13768
A6: change | B6: 5.8976378 | C6: 5.6967871 | D6: 11.39966 | E6: -469.0142 | G6: value | H6: 2308 | I6: 2330 | J6: 2357 | K6: 2897 | L6: Total Value | M6: Total Return | N6: Original Invest | O6: Return (%)
G7: 45625 | H7: =B5*H2 -> 52959 | I7: =C5*I2 -> 42828 | J7: =D5*J2 -> 98784 | K7: =E5*K2 -> 135752.48 | L7: =SUM(H7:K7) -> 330323.48 | M7: ='20241107'!M9 -> 342741.82 | N7: ='20241107'!N8 -> 265067 | O7: =(M7/N7 - 1) * 100 -> 29.303844
A8: (real) | B8: 2308 | C8: 2330 | D8: 2357 | E8: 2897 | G8: 45635 | H8: =B11*H3 -> 57855 | I8: =C11*I3 -> 52430 | J8: =D11*J3 -> 108116 | K8: =E11*K3 -> 132059.07 | L8: =SUM(H8:K8) -> 350460.07 | M8: =L8+H14-H16 -> 363055.41 | N8: =ROUNDUP(N7+B13*H3+C13*I3+D13*J3+E13*K3, 0)+H15 -> 275889 | O8: =(M8/N8 - 1) * 100 -> 31.594739
A9: weight | B9: =B10/$L$8 -> 0.165083 | C9: =C10/$L$8 -> 0.14960335 | D9: =D10/$L$8 -> 0.30849734 | E9: =E10/$L$8 -> 0.37681631 | G9: 45657 | H9: =B11*H4 -> 62422.5 | I9: =C11*I4 -> 52675 | J9: =D11*J4 -> 110264 | K9: =E11*K4 -> 131527.11 | L9: =SUM(H9:K9) -> 356888.61 | M9: =L9+H14-H16 -> 369483.95 | N9: =N8 -> 275889 | O9: =(M9/N9 - 1) * 100 -> 33.924857
